Workbook

Sheet Trade Journal
A1: NIFTY 50 OPTIONS — TRADE JOURNAL
A2: Strategy: 21 EMA (15min / 1H / Daily) + RSI Filter + S&R Rejection + OI Confirmation
A4: Date | B4: Strategy | C4: Day | D4: Time Entry | E4: Expiry | F4: Trade Type | G4: Strike | H4: Entry Price ₹ | I4: Exit Price ₹ | J4: Stop Loss ₹ | K4: Target 1 ₹ | L4: Target 2 ₹ | M4: Lots | N4: P&L ₹ | O4: Result | P4: R:R Achieved | Q4: Filters Followed | R4: Market Bias | S4: Notes / Lessons
A5: 46154 | B5: Intraday | C5: Tuesday | D5: 10:10 | E5: Weekly | F5: Put Sell | G5: 23800 PE | H5: 160.15 | I5: 171.25 | J5: 190 | K5: 161.25 | M5: 1 | N5: =(I5-H5)*M5*65 | O5: Profit | P5: =IFERROR((I5-H5)/(H5-J5),"—") | Q5: Yes | R5: Bullish | S5: Reversal trade at 23800 retest. Booked early at ~10 pts. RSI oversold bounce + theta decay on expiry day.
A6: 46155 | B6: Swing | C6: Wednesday | D6: 12:02 | E6: Monthly | F6: PE Buy | G6: 24000 PE | H6: 618.9 | I6: 0 | J6: 570 | K6: 783 | L6: 1044 | M6: 1 | N6: =(I6-H6)*M6*25 | O6: Open | P6: =IFERROR((I6-H6)/(H6-J6),"—") | Q6: Yes | R6: Bearish | S6: Deep ITM monthly PE swing. All 3 HTF bearish. Entry near 23500 ATM. Holding overnight. Grade B setup.
N7: =(H7-G7)*L7*65 | P7: =IFERROR((H7-G7)/(G7-I7),"—")
N8: =(H8-G8)*L8*65 | P8: =IFERROR((H8-G8)/(G8-I8),"—")
N9: =(H9-G9)*L9*65 | P9: =IFERROR((H9-G9)/(G9-I9),"—")
N10: =(H10-G10)*L10*65 | P10: =IFERROR((H10-G10)/(G10-I10),"—")
N11: =(H11-G11)*L11*65 | P11: =IFERROR((H11-G11)/(G11-I11),"—")
N12: =(H12-G12)*L12*65 | P12: =IFERROR((H12-G12)/(G12-I12),"—")
N13: =(H13-G13)*L13*65 | P13: =IFERROR((H13-G13)/(G13-I13),"—")
N14: =(H14-G14)*L14*65 | P14: =IFERROR((H14-G14)/(G14-I14),"—")
N15: =(H15-G15)*L15*65 | P15: =IFERROR((H15-G15)/(G15-I15),"—")
N16: =(H16-G16)*L16*65 | P16: =IFERROR((H16-G16)/(G16-I16),"—")
N17: =(H17-G17)*L17*65 | P17: =IFERROR((H17-G17)/(G17-I17),"—")
N18: =(H18-G18)*L18*65 | P18: =IFERROR((H18-G18)/(G18-I18),"—")
... N54: =(H54-G54)*L54*65 | P54: =IFERROR((H54-G54)/(G54-I54),"—")

Sheet Performance Dashboard
A1: PERFORMANCE DASHBOARD
A3: OVERALL STATS | F3: WIN / LOSS SPLIT
A4: Total Trades | B4: =COUNTA('Trade Journal'!A5:A54) | F4: By Trade Type
A5: Winning Trades | B5: =COUNTIF('Trade Journal'!O5:O54,"Profit") | F5: Type | G5: Total | H5: Wins | I5: Losses | J5: Win %
A6: Losing Trades | B6: =COUNTIF('Trade Journal'!O5:O54,"Loss") | F6: PE Buy | G6: =COUNTIF('Trade Journal'!F5:F54,"PE Buy") | H6: =COUNTIFS('Trade Journal'!F5:F54,"PE Buy",'Trade Journal'!O5:O54,"Profit") | I6: =COUNTIFS('Trade Journal'!F5:F54,"PE Buy",'Trade Journal'!O5:O54,"Loss") | J6: =IFERROR(H6/G6,0)
A7: Breakeven | B7: =COUNTIF('Trade Journal'!O5:O54,"Breakeven") | F7: CE Buy | G7: =COUNTIF('Trade Journal'!F5:F54,"CE Buy") | H7: =COUNTIFS('Trade Journal'!F5:F54,"CE Buy",'Trade Journal'!O5:O54,"Profit") | I7: =COUNTIFS('Trade Journal'!F5:F54,"CE Buy",'Trade Journal'!O5:O54,"Loss") | J7: =IFERROR(H7/G7,0)
A8: Win Rate | B8: =IFERROR(B5/B4,0) | F8: Put Sell | G8: =COUNTIF('Trade Journal'!F5:F54,"Put Sell") | H8: =COUNTIFS('Trade Journal'!F5:F54,"Put Sell",'Trade Journal'!O5:O54,"Profit") | I8: =COUNTIFS('Trade Journal'!F5:F54,"Put Sell",'Trade Journal'!O5:O54,"Loss") | J8: =IFERROR(H8/G8,0)
A9: Total P&L ₹ | B9: =SUM('Trade Journal'!N5:N54) | F9: Call Sell | G9: =COUNTIF('Trade Journal'!F5:F54,"Call Sell") | H9: =COUNTIFS('Trade Journal'!F5:F54,"Call Sell",'Trade Journal'!O5:O54,"Profit") | I9: =COUNTIFS('Trade Journal'!F5:F54,"Call Sell",'Trade Journal'!O5:O54,"Loss") | J9: =IFERROR(H9/G9,0)
A10: Avg Win ₹ | B10: =IFERROR(AVERAGEIF('Trade Journal'!O5:O54,"Profit",'Trade Journal'!N5:N54),0)
A11: Avg Loss ₹ | B11: =IFERROR(AVERAGEIF('Trade Journal'!O5:O54,"Loss",'Trade Journal'!N5:N54),0) | F11: MONTHLY P&L SUMMARY
A12: Best Trade ₹ | B12: =IFERROR(MAX('Trade Journal'!N5:N54),0) | F12: Jan | G12: =SUMPRODUCT((MONTH('Trade Journal'!A5:A54)=1)*('Trade Journal'!N5:N54))
A13: Worst Trade ₹ | B13: =IFERROR(MIN('Trade Journal'!N5:N54),0) | F13: Feb | G13: =SUMPRODUCT((MONTH('Trade Journal'!A5:A54)=2)*('Trade Journal'!N5:N54))
F14: Mar | G14: =SUMPRODUCT((MONTH('Trade Journal'!A5:A54)=3)*('Trade Journal'!N5:N54))
A15: MISTAKE TRACKER | F15: Apr | G15: =SUMPRODUCT((MONTH('Trade Journal'!A5:A54)=4)*('Trade Journal'!N5:N54))
A16: No EMA Confirm | B16: =COUNTIF('Trade Journal'!Q5:Q54,"No EMA Confirm") | F16: May | G16: =SUMPRODUCT((MONTH('Trade Journal'!A5:A54)=5)*('Trade Journal'!N5:N54))
A17: Entered at S&R | B17: =COUNTIF('Trade Journal'!Q5:Q54,"Entered at S&R") | F17: Jun | G17: =SUMPRODUCT((MONTH('Trade Journal'!A5:A54)=6)*('Trade Journal'!N5:N54))
A18: RSI Extreme | B18: =COUNTIF('Trade Journal'!Q5:Q54,"RSI Extreme") | F18: Jul | G18: =SUMPRODUCT((MONTH('Trade Journal'!A5:A54)=7)*('Trade Journal'!N5:N54))
A19: Ignored OI | B19: =COUNTIF('Trade Journal'!Q5:Q54,"Ignored OI") | F19: Aug | G19: =SUMPRODUCT((MONTH('Trade Journal'!A5:A54)=8)*('Trade Journal'!N5:N54))
F20: Sep | G20: =SUMPRODUCT((MONTH('Trade Journal'!A5:A54)=9)*('Trade Journal'!N5:N54))
F21: Oct | G21: =SUMPRODUCT((MONTH('Trade Journal'!A5:A54)=10)*('Trade Journal'!N5:N54))
F22: Nov | G22: =SUMPRODUCT((MONTH('Trade Journal'!A5:A54)=11)*('Trade Journal'!N5:N54))
F23: Dec | G23: =SUMPRODUCT((MONTH('Trade Journal'!A5:A54)=12)*('Trade Journal'!N5:N54))
A26: STRATEGY COMPARISON — Intraday vs Swing
A27: Strategy | B27: Total Trades | C27: Wins | D27: Losses | E27: Win % | F27: Total P&L ₹ | G27: Avg Win ₹ | H27: Avg Loss ₹ | I27: Best Trade ₹ | J27: Worst Trade ₹
A28: 📊 Intraday | B28: =COUNTIF('Trade Journal'!B5:B54,"Intraday") | C28: =COUNTIFS('Trade Journal'!B5:B54,"Intraday",'Trade Journal'!O5:O54,"Profit") | D28: =COUNTIFS('Trade Journal'!B5:B54,"Intraday",'Trade Journal'!O5:O54,"Loss") | E28: =IFERROR(C28/B28,0) | F28: =SUMIF('Trade Journal'!B5:B54,"Intraday",'Trade Journal'!N5:N54) | G28: =IFERROR(AVERAGEIFS('Trade Journal'!N5:N54,'Trade Journal'!B5:B54,"Intraday",'Trade Journal'!O5:O54,"Profit"),0) | H28: =IFERROR(AVERAGEIFS('Trade Journal'!N5:N54,'Trade Journal'!B5:B54,"Intraday",'Trade Journal'!O5:O54,"Loss"),0) | I28: =IFERROR(MAXIFS('Trade Journal'!N5:N54,'Trade Journal'!B5:B54,"Intraday"),0) | J28: =IFERROR(MINIFS('Trade Journal'!N5:N54,'Trade Journal'!B5:B54,"Intraday"),0)
A29: 📈 Swing | B29: =COUNTIF('Trade Journal'!B5:B54,"Swing") | C29: =COUNTIFS('Trade Journal'!B5:B54,"Swing",'Trade Journal'!O5:O54,"Profit") | D29: =COUNTIFS('Trade Journal'!B5:B54,"Swing",'Trade Journal'!O5:O54,"Loss") | E29: =IFERROR(C29/B29,0) | F29: =SUMIF('Trade Journal'!B5:B54,"Swing",'Trade Journal'!N5:N54) | G29: =IFERROR(AVERAGEIFS('Trade Journal'!N5:N54,'Trade Journal'!B5:B54,"Swing",'Trade Journal'!O5:O54,"Profit"),0) | H29: =IFERROR(AVERAGEIFS('Trade Journal'!N5:N54,'Trade Journal'!B5:B54,"Swing",'Trade Journal'!O5:O54,"Loss"),0) | I29: =IFERROR(MAXIFS('Trade Journal'!N5:N54,'Trade Journal'!B5:B54,"Swing"),0) | J29: =IFERROR(MINIFS('Trade Journal'!N5:N54,'Trade Journal'!B5:B54,"Swing"),0)
A31: 🏆 Better Strategy | B31: =IF(B28=0,"No Intraday trades yet",IF(B29=0,"No Swing trades yet",IF(E28>E29,"📊 Intraday leads — Win Rate: "&TEXT(E28,"0%")&" vs "&TEXT(E29,"0%"),"📈 Swing leads — Win Rate: "&TEXT(E29,"0%")&" vs "&TEXT(E28,"0%"))))

Sheet Strategy Rules
A1: NIFTY 50 OPTIONS — PERSONAL TRADING STRATEGY RULEBOOK
A3: FILTER 1 — 21 EMA TREND (Primary)
A4: 1 | B4: Check 15min chart first — price clearly above or below 21 EMA
A5: 2 | B5: Confirm same direction on 1H chart (must agree with 15min)
A6: 3 | B6: Confirm same direction on Daily chart (all 3 must align)
A7: 4 | B7: All 3 EMA aligned BEARISH = only PE Buy or Call Sell
A8: 5 | B8: All 3 EMA aligned BULLISH = only CE Buy or Put Sell
A9: X | B9: If 3 timeframes conflict = NO TRADE
A11: FILTER 2 — RSI ENTRY TIMING
A12: 1 | B12: Check RSI on 5min and 15min before every entry
A13: 2 | B13: RSI near or below 30 (oversold) = WAIT. Do not buy PE. Wait for RSI to recover above 35
A14: 3 | B14: RSI near or above 70 (overbought) = WAIT. Do not buy CE. Wait for RSI to pull back below 65
A15: 4 | B15: RSI between 40-60 = neutral zone — best entries happen when RSI is moving directionally
A16: REVERSAL | B16: Price making lower low + RSI making higher low at support = Put Sell entry signal
A18: FILTER 3 — SUPPORT AND RESISTANCE
A19: 1 | B19: Mark key S&R levels before market open using OI data and previous session levels
A20: 2 | B20: NEVER enter when price is sitting at S&R — wait for breakout or rejection
A21: 3 | B21: Rejection candle at resistance + EMA bearish = PE Buy entry
A22: 4 | B22: Bounce + RSI divergence at support = Put Sell entry
A23: 5 | B23: If price tested support 2-3 times = stronger bounce signal
A24: X | B24: Price mid-range between S&R = NO TRADE ZONE
A26: FILTER 4 — OI CONFIRMATION
A27: 1 | B27: Check Sensibull OI data. Max Call OI strike = ceiling resistance
A28: 2 | B28: Max Put OI strike = floor support. Never hold options against these walls
A29: 3 | B29: PCR below 0.8 = bearish bias. PCR above 1.2 = bullish bias
A30: 4 | B30: VIX rising sharply above 20 = avoid selling premium. High risk of loss
A31: 5 | B31: OI must confirm chart direction. If they conflict = skip trade
A33: RISK MANAGEMENT RULES
A34: 1 | B34: Minimum 1:2 Risk:Reward on every single trade — no exceptions
A35: 2 | B35: Book 60% of position at Target 1. Trail SL to entry for balance
A36: 3 | B36: Max 2 losing trades per day. If hit, stop trading immediately
A37: 4 | B37: Never average a losing options position — exit at SL, reassess fresh
A38: 5 | B38: Book profits before major S&R levels. Never hold hoping for more
A39: 6 | B39: 1 lot only unless confidence is very high and setup is perfect
A41: REVERSAL STRATEGY — PUT SELL AT SUPPORT
A42: Setup | B42: Price at 23,800 or 23,900 support. Tested 2+ times already
A43: Signal | B43: Price going down slowly (not crash). 5min RSI starts turning UP while price still flat/down
A44: Entry | B44: Sell 23,850 PE or 23,750 PE after RSI curl confirmed on 5min
A45: SL | B45: Nifty spot breaks support level on closing basis (15min candle close)
A46: Target | B46: 40-50% premium decay. Exit before VIX spikes or next session
...

Sheet Daily Trade Plan
A1: DAILY TRADE PLAN — NIFTY 50 OPTIONS
A3: PRE-MARKET (Before 9:15 AM)
A4: Date
A5: GIFT Nifty
A6: Global Cues | B6: Positive / Negative / Neutral
A7: India VIX
A8: Previous Close
A9: Key S&R Levels
A10: Max Call OI Strike (Ceiling)
A11: Max Put OI Strike (Floor)
A12: PCR
A13: Daily Bias | B13: Bullish / Bearish / Sideways
A15: INTRADAY LEVELS
A16: Strong Resistance
A17: Weak Resistance
A18: Current Price
A19: Weak Support
A20: Strong Support
A21: No Trade Zone
A23: TRADE SETUPS PLANNED
A24: Setup 1 — Entry Zone
A25: Setup 1 — Type | B25: PE Buy / CE Buy / Put Sell / Call Sell
A26: Setup 1 — Stop Loss
A27: Setup 1 — Target 1
A28: Setup 1 — Target 2
A29: Setup 2 — Entry Zone
A30: Setup 2 — Type
A31: Setup 2 — Stop Loss
A32: Setup 2 — Target 1
A34: END OF DAY REVIEW
A35: Trades Taken
A36: Trades Won
A37: Trades Lost
A38: P&L Today ₹
A39: Rules Followed? | B39: Yes / No
A40: Biggest Mistake
A41: Key Learning
A42: Tomorrow's Plan
